Workbook

Sheet Catalogue LLM
A1: C4RBON GROUP - Simulateur Credits IA Kinn
A2: Taux EUR/USD | B2: 1.08
A4: Fournisseur | B4: Modele | C4: Input ($/1M tokens) | D4: Output ($/1M tokens) | E4: Input (EUR/1M tokens) | F4: Output (EUR/1M tokens) | G4: Context window | H4: Notes
A5: OpenAI | B5: gpt-4o | C5: 2.5 | D5: 10 | E5: =C5/$B$2 -> 2.3148148 | F5: =D5/$B$2 -> 9.2592593 | G5: 128K | H5: Principal
A6: OpenAI | B6: gpt-4o-mini | C6: 0.15 | D6: 0.6 | E6: =C6/$B$2 -> 0.13888889 | F6: =D6/$B$2 -> 0.55555556 | G6: 128K | H6: Taches simples
A7: OpenAI | B7: gpt-4.1 | C7: 2 | D7: 8 | E7: =C7/$B$2 -> 1.8518519 | F7: =D7/$B$2 -> 7.4074074 | G7: 1M | H7: Dernier modele
A8: OpenAI | B8: gpt-4.1-mini | C8: 0.4 | D8: 1.6 | E8: =C8/$B$2 -> 0.37037037 | F8: =D8/$B$2 -> 1.4814815 | G8: 1M | H8: Mini dernier
A9: OpenAI | B9: gpt-4.1-nano | C9: 0.1 | D9: 0.4 | E9: =C9/$B$2 -> 0.092592593 | F9: =D9/$B$2 -> 0.37037037 | G9: 1M | H9: Ultra low cost
A10: OpenAI | B10: o3 | C10: 2 | D10: 8 | E10: =C10/$B$2 -> 1.8518519 | F10: =D10/$B$2 -> 7.4074074 | G10: 200K | H10: Reasoning
A11: OpenAI | B11: o4-mini | C11: 1.1 | D11: 4.4 | E11: =C11/$B$2 -> 1.0185185 | F11: =D11/$B$2 -> 4.0740741 | G11: 200K | H11: Reasoning mini
A12: Anthropic | B12: claude-sonnet-4 | C12: 3 | D12: 15 | E12: =C12/$B$2 -> 2.7777778 | F12: =D12/$B$2 -> 13.888889 | G12: 200K | H12: Principal
A13: Anthropic | B13: claude-haiku-3.5 | C13: 0.8 | D13: 4 | E13: =C13/$B$2 -> 0.74074074 | F13: =D13/$B$2 -> 3.7037037 | G13: 200K | H13: Rapide

Sheet Cout par utilisation
A1: C4RBON GROUP - Simulateur Credits IA Kinn
A3: A. Parametres d'utilisation type
A4: Modele principal utilise | B4: gpt-4o-mini
A5: Tokens input moyens par requete | B5: 2000
A6: Tokens output moyens par requete | B6: 500
A7: Cout input/1M tokens (EUR) | B7: =VLOOKUP(B4,'Catalogue LLM'!B5:F13,4,FALSE()) -> 0.13888889
A8: Cout output/1M tokens (EUR) | B8: =VLOOKUP(B4,'Catalogue LLM'!B5:F13,5,FALSE()) -> 0.55555556
A10: Cout input par requete | B10: =(B5/1000000)*B7 -> 0.00027777778
A11: Cout output par requete | B11: =(B6/1000000)*B8 -> 0.00027777778
A12: Cout total par requete IA | B12: =B10+B11 -> 0.00055555556
A15: B. Simulation usage par client
A16: Requetes IA par jour (moyenne) | B16: 20
A17: Jours actifs par mois | B17: 22
A18: Requetes IA par mois | B18: =B16*B17 -> 440
A19: Cout IA par client/mois | B19: =B18*B12 -> 0.24444444
A21: Requetes workflow par jour | B21: 50
A22: Requetes workflow par mois | B22: =B21*B17 -> 1100
A23: Cout execution workflow/requete | B23: 0.0001
A24: Cout workflow par client/mois | B24: =B22*B23 -> 0.11
A26: Cout total par client/mois | B26: =B19+B24 -> 0.35444444
A29: C. Projection par nombre de clients
A30: Clients | B30: Cout IA mensuel | C30: Cout workflow mensuel | D30: Cout total mensuel | E30: Cout total annuel
A31: 10 | B31: =A31*$B$19 -> 2.4444444 | C31: =A31*$B$24 -> 1.1 | D31: =B31+C31 -> 3.5444444 | E31: =D31*12 -> 42.533333
A32: 25 | B32: =A32*$B$19 -> 6.1111111 | C32: =A32*$B$24 -> 2.75 | D32: =B32+C32 -> 8.8611111 | E32: =D32*12 -> 106.33333
A33: 50 | B33: =A33*$B$19 -> 12.222222 | C33: =A33*$B$24 -> 5.5 | D33: =B33+C33 -> 17.722222 | E33: =D33*12 -> 212.66667
A34: 100 | B34: =A34*$B$19 -> 24.444444 | C34: =A34*$B$24 -> 11 | D34: =B34+C34 -> 35.444444 | E34: =D34*12 -> 425.33333
A35: 200 | B35: =A35*$B$19 -> 48.888889 | C35: =A35*$B$24 -> 22 | D35: =B35+C35 -> 70.888889 | E35: =D35*12 -> 850.66667
A36: 500 | B36: =A36*$B$19 -> 122.22222 | C36: =A36*$B$24 -> 55 | D36: =B36+C36 -> 177.22222 | E36: =D36*12 -> 2126.6667
A37: 1000 | B37: =A37*$B$19 -> 244.44444 | C37: =A37*$B$24 -> 110 | D37: =B37+C37 -> 354.44444 | E37: =D37*12 -> 4253.3333

Sheet Grille Credits
A1: C4RBON GROUP - Simulateur Credits IA Kinn
A3: A. Definition du credit
A4: Tokens input par credit | B4: 50000
A5: Tokens output par credit | B5: 12500
A6: Modele de reference | B6: gpt-4o-mini
A7: Cout input/1M tokens (EUR) | B7: 0.14
A8: Cout output/1M tokens (EUR) | B8: 0.56
A9: Cout reel par credit | B9: =(B4/1000000)*B7+(B5/1000000)*B8 -> 0.014
A10: Requetes IA equivalentes par credit | B10: =B4/2000 -> 25
A12: B. Packs inclus dans l'abonnement
A13: Abonnement | B13: Prix/mois (EUR) | C13: Credits inclus | D13: Cout reel credits | E13: Marge sur credits | F13: Valeur credit (EUR) | G13: Requetes IA incluses
A14: Starter | B14: 49 | C14: 100 | D14: =C14*$B$9 -> 1.4 | E14: =B14-D14 -> 47.6 | F14: =B14/C14 -> 0.49 | G14: =C14*$B$10 -> 2500
A15: Pro | B15: 99 | C15: 300 | D15: =C15*$B$9 -> 4.2 | E15: =B15-D15 -> 94.8 | F15: =B15/C15 -> 0.33 | G15: =C15*$B$10 -> 7500
A16: Business | B16: 199 | C16: 800 | D16: =C16*$B$9 -> 11.2 | E16: =B16-D16 -> 187.8 | F16: =B16/C16 -> 0.24875 | G16: =C16*$B$10 -> 20000
A17: Enterprise | B17: 499 | C17: 2500 | D17: =C17*$B$9 -> 35 | E17: =B17-D17 -> 464 | F17: =B17/C17 -> 0.1996 | G17: =C17*$B$10 -> 62500
A19: C. Recharges pour abonnes (prix reduit)
A20: Ref prix/credit standalone (Pack 100) | B20: =D31 -> 0.169
A21: Pack | B21: Credits | C21: Prix (EUR) | D21: Prix/credit | E21: Cout reel | F21: Marge | G21: Marge % | H21: Remise vs standalone
A22: Recharge S | B22: 100 | C22: 9.9 | D22: =C22/B22 -> 0.099 | E22: =B22*$B$9 -> 1.4 | F22: =C22-E22 -> 8.5 | G22: =F22/C22 -> 0.85858586 | H22: =1-(D22/D43) -> -6.0714286
A23: Recharge M | B23: 250 | C23: 19.9 | D23: =C23/B23 -> 0.0796 | E23: =B23*$B$9 -> 3.5 | F23: =C23-E23 -> 16.4 | G23: =F23/C23 -> 0.8241206 | H23: =1-(D23/D43) -> -4.6857143
A24: Recharge L | B24: 500 | C24: 34.9 | D24: =C24/B24 -> 0.0698 | E24: =B24*$B$9 -> 7 | F24: =C24-E24 -> 27.9 | G24: =F24/C24 -> 0.79942693 | H24: =1-(D24/D43) -> -3.9857143
A25: Recharge XL | B25: 1000 | C25: 59.9 | D25: =C25/B25 -> 0.0599 | E25: =B25*$B$9 -> 14 | F25: =C25-E25 -> 45.9 | G25: =F25/C25 -> 0.76627713 | H25: =1-(D25/D43) -> -3.2785714
A26: Recharge XXL | B26: 2500 | C26: 129.9 | D26: =C26/B26 -> 0.05196 | E26: =B26*$B$9 -> 35 | F26: =C26-E26 -> 94.9 | G26: =F26/C26 -> 0.73056197 | H26: =1-(D26/D43) -> -2.7114286
A28: D. Packs standalone (sans abonnement)
A29: Pack | B29: Credits | C29: Prix (EUR) | D29: Prix/credit | E29: Cout reel | F29: Marge | G29: Marge %
A30: Pack 50 | B30: 50 | C30: 9.9 | D30: =C30/B30 -> 0.198 | E30: =B30*$B$9 -> 0.7 | F30: =C30-E30 -> 9.2 | G30: =F30/C30 -> 0.92929293
A31: Pack 100 | B31: 100 | C31: 16.9 | D31: =C31/B31 -> 0.169 | E31: =B31*$B$9 -> 1.4 | F31: =C31-E31 -> 15.5 | G31: =F31/C31 -> 0.91715976
A32: Pack 250 | B32: 250 | C32: 34.9 | D32: =C32/B32 -> 0.1396 | E32: =B32*$B$9 -> 3.5 | F32: =C32-E32 -> 31.4 | G32: =F32/C32 -> 0.89971347
A33: Pack 500 | B33: 500 | C33: 59.9 | D33: =C33/B33 -> 0.1198 | E33: =B33*$B$9 -> 7 | F33: =C33-E33 -> 52.9 | G33: =F33/C33 -> 0.88313856
A34: Pack 1000 | B34: 1000 | C34: 99.9 | D34: =C34/B34 -> 0.0999 | E34: =B34*$B$9 -> 14 | F34: =C34-E34 -> 85.9 | G34: =F34/C34 -> 0.85985986
A36: E. Comparatif prix/credit
A37: Source | B37: Credits | C37: Prix/credit (EUR) | D37: Cout reel/credit | E37: Marge %
A38: Starter (abo) | B38: =C14 -> 100 | C38: =F14 -> 0.49 | D38: =$B$9 -> 0.014 | E38: =(C38-D38)/C38 -> 0.97142857
A39: Pro (abo) | B39: =C15 -> 300 | C39: =F15 -> 0.33 | D39: =$B$9 -> 0.014 | E39: =(C39-D39)/C39 -> 0.95757576
A40: Business (abo) | B40: =C16 -> 800 | C40: =F16 -> 0.24875 | D40: =$B$9 -> 0.014 | E40: =(C40-D40)/C40 -> 0.94371859
A41: Enterprise (abo) | B41: =C17 -> 2500 | C41: =F17 -> 0.1996 | D41: =$B$9 -> 0.014 | E41: =(C41-D41)/C41 -> 0.92985972
A42: Recharge S | B42: =B22 -> 100 | C42: =D22 -> 0.099 | D42: =$B$9 -> 0.014 | E42: =G22 -> 0.85858586
A43: Recharge XL | B43: =B25 -> 1000 | C43: =D25 -> 0.0599 | D43: =$B$9 -> 0.014 | E43: =G25 -> 0.76627713
A44: Standalone 50 | B44: =B30 -> 50 | C44: =D30 -> 0.198 | D44: =$B$9 -> 0.014 | E44: =G30 -> 0.92929293
A45: Standalone 1000 | B45: =B34 -> 1000 | C45: =D34 -> 0.0999 | D45: =$B$9 -> 0.014 | E45: =G34 -> 0.85985986

Sheet Simulation Revenus
A1: C4RBON GROUP - Simulateur Credits IA Kinn
A3: A. Mix utilisateurs
A4: Clients Starter | B4: 100
A5: Clients Pro | B5: 50
A6: Clients Business | B6: 20
A7: Clients Enterprise | B7: 5
A8: Total clients | B8: =SUM(B4:B7) -> 175
A10: % qui achetent des recharges | B10: 0.3
A11: Recharges moyennes/client/mois | B11: 1.5
A12: Pack recharge moyen (EUR) | B12: 19.9
A18: B. Revenus mensuels
A19: Revenus Starter | B19: =B4*'Grille Credits'!B14 -> 4900
A20: Revenus Pro | B20: =B5*'Grille Credits'!B15 -> 4950
A21: Revenus Business | B21: =B6*'Grille Credits'!B16 -> 3980
A22: Revenus Enterprise | B22: =B7*'Grille Credits'!B17 -> 2495
A23: Total abonnements | B23: =SUM(B19:B22) -> 16325
A25: Revenus recharges | B25: =B8*B10*B11*B12 -> 1567.125
A27: REVENU TOTAL MENSUEL | B27: =B23+B25 -> 17892.125
A28: REVENU TOTAL ANNUEL | B28: =B27*12 -> 214705.5
A33: C. Couts mensuels
A34: Cout IA (credits consommes) | B34: =(B4*'Grille Credits'!C14+B5*'Grille Credits'!C15+B6*'Grille Credits'!C16+B7*'Grille Credits'!C17)*'Grille Credits'!$B$9 + B8*B10*B11*100*'Grille Credits'!$B$9 -> 859.25
A35: Cout AWS infrastructure | B35: 0
A36: Total couts | B36: =B34+B35 -> 859.25
A38: MARGE BRUTE MENSUELLE | B38: =B27-B36 -> 17032.875
A39: MARGE BRUTE % | B39: =IF(B27=0,0,B38/B27) -> 0.95197608
A40: MARGE BRUTE ANNUELLE | B40: =B38*12 -> 204394.5
A43: D. Projection 12 mois
A44: Croissance mensuelle clients | B44: 0.1
A46: Mois | B46: Clients | C46: Revenus Abo | D46: Revenus Recharges | E46: Total Revenus | F46: Cout IA | G46: Cout AWS | H46: Marge
A47: 1 | B47: =B8 -> 175 | C47: =IF($B$8=0,0,B47*($B$23/$B$8)) -> 16325 | D47: =B47*$B$10*$B$11*$B$12 -> 1567.125 | E47: =C47+D47 -> 17892.125 | F47: =IF($B$8=0,0,B47*($B$34/$B$8)) -> 859.25 | G47: =$B$35 -> 0 | H47: =E47-F47-G47 -> 17032.875
A48: 2 | B48: =ROUND(B47*(1+$B$44),0) -> 193 | C48: =IF($B$8=0,0,B48*($B$23/$B$8)) -> 18004.143 | D48: =B48*$B$10*$B$11*$B$12 -> 1728.315 | E48: =C48+D48 -> 19732.458 | F48: =IF($B$8=0,0,B48*($B$34/$B$8)) -> 947.63 | G48: =$B$35 -> 0 | H48: =E48-F48-G48 -> 18784.828
A49: 3 | B49: =ROUND(B48*(1+$B$44),0) -> 212 | C49: =IF($B$8=0,0,B49*($B$23/$B$8)) -> 19776.571 | D49: =B49*$B$10*$B$11*$B$12 -> 1898.46 | E49: =C49+D49 -> 21675.031 | F49: =IF($B$8=0,0,B49*($B$34/$B$8)) -> 1040.92 | G49: =$B$35 -> 0 | H49: =E49-F49-G49 -> 20634.111
A50: 4 | B50: =ROUND(B49*(1+$B$44),0) -> 233 | C50: =IF($B$8=0,0,B50*($B$23/$B$8)) -> 21735.571 | D50: =B50*$B$10*$B$11*$B$12 -> 2086.515 | E50: =C50+D50 -> 23822.086 | F50: =IF($B$8=0,0,B50*($B$34/$B$8)) -> 1144.03 | G50: =$B$35 -> 0 | H50: =E50-F50-G50 -> 22678.056
A51: 5 | B51: =ROUND(B50*(1+$B$44),0) -> 256 | C51: =IF($B$8=0,0,B51*($B$23/$B$8)) -> 23881.143 | D51: =B51*$B$10*$B$11*$B$12 -> 2292.48 | E51: =C51+D51 -> 26173.623 | F51: =IF($B$8=0,0,B51*($B$34/$B$8)) -> 1256.96 | G51: =$B$35 -> 0 | H51: =E51-F51-G51 -> 24916.663
A52: 6 | B52: =ROUND(B51*(1+$B$44),0) -> 282 | C52: =IF($B$8=0,0,B52*($B$23/$B$8)) -> 26306.571 | D52: =B52*$B$10*$B$11*$B$12 -> 2525.31 | E52: =C52+D52 -> 28831.881 | F52: =IF($B$8=0,0,B52*($B$34/$B$8)) -> 1384.62 | G52: =$B$35 -> 0 | H52: =E52-F52-G52 -> 27447.261
A53: 7 | B53: =ROUND(B52*(1+$B$44),0) -> 310 | C53: =IF($B$8=0,0,B53*($B$23/$B$8)) -> 28918.571 | D53: =B53*$B$10*$B$11*$B$12 -> 2776.05 | E53: =C53+D53 -> 31694.621 | F53: =IF($B$8=0,0,B53*($B$34/$B$8)) -> 1522.1 | G53: =$B$35 -> 0 | H53: =E53-F53-G53 -> 30172.521
A54: 8 | B54: =ROUND(B53*(1+$B$44),0) -> 341 | C54: =IF($B$8=0,0,B54*($B$23/$B$8)) -> 31810.429 | D54: =B54*$B$10*$B$11*$B$12 -> 3053.655 | E54: =C54+D54 -> 34864.084 | F54: =IF($B$8=0,0,B54*($B$34/$B$8)) -> 1674.31 | G54: =$B$35 -> 0 | H54: =E54-F54-G54 -> 33189.774
A55: 9 | B55: =ROUND(B54*(1+$B$44),0) -> 375 | C55: =IF($B$8=0,0,B55*($B$23/$B$8)) -> 34982.143 | D55: =B55*$B$10*$B$11*$B$12 -> 3358.125 | E55: =C55+D55 -> 38340.268 | F55: =IF($B$8=0,0,B55*($B$34/$B$8)) -> 1841.25 | G55: =$B$35 -> 0 | H55: =E55-F55-G55 -> 36499.018
A56: 10 | B56: =ROUND(B55*(1+$B$44),0) -> 413 | C56: =IF($B$8=0,0,B56*($B$23/$B$8)) -> 38527 | D56: =B56*$B$10*$B$11*$B$12 -> 3698.415 | E56: =C56+D56 -> 42225.415 | F56: =IF($B$8=0,0,B56*($B$34/$B$8)) -> 2027.83 | G56: =$B$35 -> 0 | H56: =E56-F56-G56 -> 40197.585
A57: 11 | B57: =ROUND(B56*(1+$B$44),0) -> 454 | C57: =IF($B$8=0,0,B57*($B$23/$B$8)) -> 42351.714 | D57: =B57*$B$10*$B$11*$B$12 -> 4065.57 | E57: =C57+D57 -> 46417.284 | F57: =IF($B$8=0,0,B57*($B$34/$B$8)) -> 2229.14 | G57: =$B$35 -> 0 | H57: =E57-F57-G57 -> 44188.144
...

Sheet Modeles IA
A1: C4RBON GROUP - Simulateur Credits IA Kinn
A3: Comparaison des modeles - Impact sur les marges
A4: Tokens input par requete | B4: 2000
A5: Tokens output par requete | B5: 500
A6: Ref: Prix credit Pro (EUR) | B6: ='Grille Credits'!F15 -> 0.33
A8: Modele | B8: Cout/requete (EUR) | C8: Requetes par credit | D8: Cout reel/credit | E8: Marge/credit (Pack Pro) | F8: Impact marge si 100% ce modele
A9: ='Catalogue LLM'!B5 -> gpt-4o | B9: =($B$4/1000000)*'Catalogue LLM'!E5+($B$5/1000000)*'Catalogue LLM'!F5 -> 0.0092592593 | C9: ='Grille Credits'!$B$4/$B$4 -> 25 | D9: =('Grille Credits'!$B$4/1000000)*'Catalogue LLM'!E5+('Grille Credits'!$B$5/1000000)*'Catalogue LLM'!F5 -> 0.23148148 | E9: =$B$6-D9 -> 0.098518519 | F9: =IF($B$6=0,0,E9/$B$6) -> 0.29854097
A10: ='Catalogue LLM'!B6 -> gpt-4o-mini | B10: =($B$4/1000000)*'Catalogue LLM'!E6+($B$5/1000000)*'Catalogue LLM'!F6 -> 0.00055555556 | C10: ='Grille Credits'!$B$4/$B$4 -> 25 | D10: =('Grille Credits'!$B$4/1000000)*'Catalogue LLM'!E6+('Grille Credits'!$B$5/1000000)*'Catalogue LLM'!F6 -> 0.013888889 | E10: =$B$6-D10 -> 0.31611111 | F10: =IF($B$6=0,0,E10/$B$6) -> 0.95791246
A11: ='Catalogue LLM'!B7 -> gpt-4.1 | B11: =($B$4/1000000)*'Catalogue LLM'!E7+($B$5/1000000)*'Catalogue LLM'!F7 -> 0.0074074074 | C11: ='Grille Credits'!$B$4/$B$4 -> 25 | D11: =('Grille Credits'!$B$4/1000000)*'Catalogue LLM'!E7+('Grille Credits'!$B$5/1000000)*'Catalogue LLM'!F7 -> 0.18518519 | E11: =$B$6-D11 -> 0.14481481 | F11: =IF($B$6=0,0,E11/$B$6) -> 0.43883277
A12: ='Catalogue LLM'!B8 -> gpt-4.1-mini | B12: =($B$4/1000000)*'Catalogue LLM'!E8+($B$5/1000000)*'Catalogue LLM'!F8 -> 0.0014814815 | C12: ='Grille Credits'!$B$4/$B$4 -> 25 | D12: =('Grille Credits'!$B$4/1000000)*'Catalogue LLM'!E8+('Grille Credits'!$B$5/1000000)*'Catalogue LLM'!F8 -> 0.037037037 | E12: =$B$6-D12 -> 0.29296296 | F12: =IF($B$6=0,0,E12/$B$6) -> 0.88776655
A13: ='Catalogue LLM'!B9 -> gpt-4.1-nano | B13: =($B$4/1000000)*'Catalogue LLM'!E9+($B$5/1000000)*'Catalogue LLM'!F9 -> 0.00037037037 | C13: ='Grille Credits'!$B$4/$B$4 -> 25 | D13: =('Grille Credits'!$B$4/1000000)*'Catalogue LLM'!E9+('Grille Credits'!$B$5/1000000)*'Catalogue LLM'!F9 -> 0.0092592593 | E13: =$B$6-D13 -> 0.32074074 | F13: =IF($B$6=0,0,E13/$B$6) -> 0.97194164
A14: ='Catalogue LLM'!B10 -> o3 | B14: =($B$4/1000000)*'Catalogue LLM'!E10+($B$5/1000000)*'Catalogue LLM'!F10 -> 0.0074074074 | C14: ='Grille Credits'!$B$4/$B$4 -> 25 | D14: =('Grille Credits'!$B$4/1000000)*'Catalogue LLM'!E10+('Grille Credits'!$B$5/1000000)*'Catalogue LLM'!F10 -> 0.18518519 | E14: =$B$6-D14 -> 0.14481481 | F14: =IF($B$6=0,0,E14/$B$6) -> 0.43883277
A15: ='Catalogue LLM'!B11 -> o4-mini | B15: =($B$4/1000000)*'Catalogue LLM'!E11+($B$5/1000000)*'Catalogue LLM'!F11 -> 0.0040740741 | C15: ='Grille Credits'!$B$4/$B$4 -> 25 | D15: =('Grille Credits'!$B$4/1000000)*'Catalogue LLM'!E11+('Grille Credits'!$B$5/1000000)*'Catalogue LLM'!F11 -> 0.10185185 | E15: =$B$6-D15 -> 0.22814815 | F15: =IF($B$6=0,0,E15/$B$6) -> 0.69135802
A16: ='Catalogue LLM'!B12 -> claude-sonnet-4 | B16: =($B$4/1000000)*'Catalogue LLM'!E12+($B$5/1000000)*'Catalogue LLM'!F12 -> 0.0125 | C16: ='Grille Credits'!$B$4/$B$4 -> 25 | D16: =('Grille Credits'!$B$4/1000000)*'Catalogue LLM'!E12+('Grille Credits'!$B$5/1000000)*'Catalogue LLM'!F12 -> 0.3125 | E16: =$B$6-D16 -> 0.0175 | F16: =IF($B$6=0,0,E16/$B$6) -> 0.053030303
A17: ='Catalogue LLM'!B13 -> claude-haiku-3.5 | B17: =($B$4/1000000)*'Catalogue LLM'!E13+($B$5/1000000)*'Catalogue LLM'!F13 -> 0.0033333333 | C17: ='Grille Credits'!$B$4/$B$4 -> 25 | D17: =('Grille Credits'!$B$4/1000000)*'Catalogue LLM'!E13+('Grille Credits'!$B$5/1000000)*'Catalogue LLM'!F13 -> 0.083333333 | E17: =$B$6-D17 -> 0.24666667 | F17: =IF($B$6=0,0,E17/$B$6) -> 0.74747475
